[33m[W 170302 10:03:34 web:1545](B[m 404 GET /project/project/list (192.168.15.94): not found
[33m[W 170302 10:44:49 web:1545](B[m 404 GET /project/project/list (192.168.15.94): not found
[33m[W 170302 10:44:55 web:1545](B[m 404 GET /project//list (192.168.15.94): not found
[32m[I 170302 10:52:08 autoreload:204](B[m /data/www/python/www.torngas.com/demo/settings/setting.py modified; restarting server
[31m[E 170302 10:52:11 web:1548](B[m Uncaught exception GET /project/list (192.168.15.59)
    HttpRequest(protocol='http', host='192.168.15.59:8000', method='GET', uri='/project/list', version='HTTP/1.1', remote_ip='192.168.15.59', headers={'Accept-Language': 'zh-CN,zh;q=0.8,en;q=0.6', 'Accept-Encoding': 'gzip, deflate, sdch', 'Host': '192.168.15.59:8000', 'Accept': 'text/html,application/xhtml+xml,application/xml;q=0.9,image/webp,*/*;q=0.8', 'User-Agent': 'Mozilla/5.0 (Macintosh; Intel Mac OS X 10_10_5) AppleWebKit/537.36 (KHTML, like Gecko) Chrome/56.0.2924.87 Safari/537.36', 'Connection': 'keep-alive', 'Referer': 'http://192.168.15.59:8000/project/add', 'Cache-Control': 'max-age=0', 'If-None-Match': '"4b2ad71788ca3cca5cc756c22305d329de52aeb0"', 'Upgrade-Insecure-Requests': '1', 'Cookie': '_xsrf=2|d75a1014|e581bca06d575a45cdcf59f7794dde3d|1488251160; __TORNADOSSID=F72D24A6A25A022CC83B7F0DD5B1A578CECC16A1|EtdHjDO1'})
    Traceback (most recent call last):
      File "/Library/Python/2.7/site-packages/tornado/web.py", line 1467, in _execute
        result = method(*self.path_args, **self.path_kwargs)
      File "/data/www/python/www.torngas.com/demo/helloworld/handlers/project_handler.py", line 19, in get
        project_list = project.GetProjectByCondition(self)
      File "/data/www/python/www.torngas.com/demo/helloworld/models/project_models.py", line 29, in GetProjectByCondition
        project_list = Project.session.query(Project).order_by(Project.id.desc()).all()
      File "/Library/Python/2.7/site-packages/sqlalchemy/orm/query.py", line 2638, in all
        return list(self)
      File "/Library/Python/2.7/site-packages/sqlalchemy/orm/query.py", line 2790, in __iter__
        return self._execute_and_instances(context)
      File "/Library/Python/2.7/site-packages/sqlalchemy/orm/query.py", line 2811, in _execute_and_instances
        close_with_result=True)
      File "/Library/Python/2.7/site-packages/sqlalchemy/orm/query.py", line 2820, in _get_bind_args
        **kw
      File "/Library/Python/2.7/site-packages/sqlalchemy/orm/query.py", line 2802, in _connection_from_session
        conn = self.session.connection(**kw)
      File "/Library/Python/2.7/site-packages/sqlalchemy/orm/session.py", line 966, in connection
        execution_options=execution_options)
      File "/Library/Python/2.7/site-packages/sqlalchemy/orm/session.py", line 971, in _connection_for_bind
        engine, execution_options)
      File "/Library/Python/2.7/site-packages/sqlalchemy/orm/session.py", line 403, in _connection_for_bind
        conn = bind.contextual_connect()
      File "/Library/Python/2.7/site-packages/sqlalchemy/engine/base.py", line 2103, in contextual_connect
        self._wrap_pool_connect(self.pool.connect, None),
      File "/Library/Python/2.7/site-packages/sqlalchemy/engine/base.py", line 2142, in _wrap_pool_connect
        e, dialect, self)
      File "/Library/Python/2.7/site-packages/sqlalchemy/engine/base.py", line 1456, in _handle_dbapi_exception_noconnection
        exc_info
      File "/Library/Python/2.7/site-packages/sqlalchemy/util/compat.py", line 203, in raise_from_cause
        reraise(type(exception), exception, tb=exc_tb, cause=cause)
      File "/Library/Python/2.7/site-packages/sqlalchemy/engine/base.py", line 2138, in _wrap_pool_connect
        return fn()
      File "/Library/Python/2.7/site-packages/sqlalchemy/pool.py", line 387, in connect
        return _ConnectionFairy._checkout(self)
      File "/Library/Python/2.7/site-packages/sqlalchemy/pool.py", line 766, in _checkout
        fairy = _ConnectionRecord.checkout(pool)
      File "/Library/Python/2.7/site-packages/sqlalchemy/pool.py", line 516, in checkout
        rec = pool._do_get()
      File "/Library/Python/2.7/site-packages/sqlalchemy/pool.py", line 1138, in _do_get
        self._dec_overflow()
      File "/Library/Python/2.7/site-packages/sqlalchemy/util/langhelpers.py", line 60, in __exit__
        compat.reraise(exc_type, exc_value, exc_tb)
      File "/Library/Python/2.7/site-packages/sqlalchemy/pool.py", line 1135, in _do_get
        return self._create_connection()
      File "/Library/Python/2.7/site-packages/sqlalchemy/pool.py", line 333, in _create_connection
        return _ConnectionRecord(self)
      File "/Library/Python/2.7/site-packages/sqlalchemy/pool.py", line 461, in __init__
        self.__connect(first_connect_check=True)
      File "/Library/Python/2.7/site-packages/sqlalchemy/pool.py", line 651, in __connect
        connection = pool._invoke_creator(self)
      File "/Library/Python/2.7/site-packages/sqlalchemy/engine/strategies.py", line 105, in connect
        return dialect.connect(*cargs, **cparams)
      File "/Library/Python/2.7/site-packages/sqlalchemy/engine/default.py", line 393, in connect
        return self.dbapi.connect(*cargs, **cparams)
      File "/Library/Python/2.7/site-packages/MySQLdb/__init__.py", line 81, in Connect
        return Connection(*args, **kwargs)
      File "/Library/Python/2.7/site-packages/MySQLdb/connections.py", line 193, in __init__
        super(Connection, self).__init__(*args, **kwargs2)
    OperationalError: (_mysql_exceptions.OperationalError) (1044, "Access denied for user 'mysql'@'localhost' to database 'sync'")
